Workbook

Sheet Altan
A1: TARIH | B1: Tip | C1: Tip | D1: İSİM | E1: Not | F1: TUTAR | G1: ÖDENEN | H1: Ödenen Temmuz | I1: Notlar | J1: KALAN | K1: Faiz | L1: Temmuz
A2: 45947 | B2: Şahsi | C2: Kart | D2: Emirhan Gürbüz kart Garanti | E2: Bitti | F2: 225400 | H2: 225400 | J2: =F2-G2-H2 -> 0
A3: 45947 | B3: Şahsi | C3: Borc | D3: Hasan Haykir | E3: Bitti | F3: 3526245 | G3: 1970000 | H3: 1556245 | J3: =F3-G3-H3 -> 0 | N3: =J3 -> 0 | O3: =N3+H3 -> 1556245
A4: 46010 | B4: Firma | C4: Kart | D4: Nexgen kimya Finansbak | F4: 219000 | H4: 219000 | I4: Aktif | J4: =F4-G4-H4 -> 0
A5: 45991 | B5: Şahsi | C5: Kart | D5: Esra orhan | F5: 750000 | H5: 300000 | J5: =F5-G5-H5 -> 450000
A6: 45968 | B6: Sahsi | C6: Kart | D6: Adem İbrahimoğlu | E6: Bitti | F6: 542750 | G6: 542750 | J6: =F6-G6-H6 -> 0
A7: 45972 | B7: sahsi | C7: Kart | D7: Metin can biyik akbank kubi | E7: Bitti | F7: 250000 | G7: 250000 | J7: =F7-G7-H7 -> 0
A8: 45972 | B8: Firma | C8: Kart | D8: Sahin taban finansbank kart | F8: 720000 | G8: 120000 | J8: =F8-G8-H8 -> 600000
A9: 45972 | B9: Şahsi | C9: Kredi | D9: Umit Terzi Kredi | E9: Bitti | F9: 35463.78 | G9: 35463.78 | J9: =F9-G9-H9 -> 0
A10: 45984 | B10: Şahsi | C10: Kart | D10: Altan terzi. Garanti | E10: Bitti | F10: 648116 | G10: 648116 | I10: Kart Kapandı | J10: =F10-G10-H10 -> 0
A11: 46014 | B11: sahsi | C11: kart | D11: Metin tuncer kart | F11: 1037075.7 | H11: 700000 | J11: =F11-G11-H11 -> 337075.73 | N11: =J11 -> 337075.73
A12: 45988 | B12: Şahsi | C12: Kart | D12: Altan terzi. Ziraat | E12: Bitti | F12: 232000 | G12: 232000 | I12: Aktif | J12: =F12-G12-H12 -> 0 | N12: =J12 -> 0
A13: 45991 | B13: Sahsi | C13: Kart | D13: Ibrahim KILIC | E13: Bitti | F13: 650000 | G13: 650000 | J13: =F13-G13-H13 -> 0 | N13: =J13 -> 0
A14: 45997 | B14: sahsi | C14: kart | D14: Sahin terzi garanti | E14: Bitti | F14: 180000 | G14: 180000 | I14: Kapanacak | J14: =F14-G14-H14 -> 0 | N14: =J14 -> 0
A15: 45998 | B15: Sahsi | C15: Kart | D15: Seydanur haykir | E15: Bitti | F15: 800000 | G15: 800000 | J15: =F15-G15-H15 -> 0 | N15: =J15 -> 0
A16: 45999 | B16: Sahsi | C16: Kart | D16: Hasan Haykir vakifbank | E16: Bitti | F16: 425000 | G16: 425000 | J16: =F16-G16-H16 -> 0 | N16: =J16 -> 0
A17: 46000 | B17: Sahsi | C17: Kart | D17: Hasan Haykir Garanti | E17: Bitti | F17: 844000 | G17: 844000 | J17: =F17-G17-H17 -> 0 | N17: =J17 -> 0
A18: 45967 | B18: Şahsi | C18: Kredi | D18: Finans kredi EO | E18: Bitti | F18: 70813 | G18: 70813 | J18: =F18-G18-H18 -> 0
A19: 45997 | B19: Şahsi | C19: Kredi | D19: Finans kredi EO | E19: Bitti | F19: 70813 | G19: 70813 | J19: =F19-G19-H19 -> 0
A20: 46087 | B20: Şahsi | C20: Kredi | D20: Finans kredi EO | F20: 70813 | G20: 70813 | J20: =F20-G20-H20 -> 0
A21: 46059 | B21: Şahsi | C21: Kredi | D21: Finans kredi EO | F21: 70813 | G21: 70813 | J21: =F21-G21-H21 -> 0
A22: 45966 | B22: sahsi | C22: Kart | D22: Kubilay kart Garanti | E22: Bitti | F22: 247000 | G22: 247000 | J22: =F22-G22-H22 -> 0
A23: 45966 | B23: Şahsi | C23: Kredi | D23: Kubilay kredi | E23: Bitti | F23: 82491.36 | G23: 82491.36 | J23: =F23-G23-H23 -> 0
A24: 45996 | B24: Şahsi | C24: Kredi | D24: Kubilay kredi | E24: Bitti | F24: 82491.36 | G24: 82491.36 | J24: =F24-G24-H24 -> 0
A25: 46027 | B25: Şahsi | C25: Kredi | D25: Kubilay kredi | F25: 82491.36 | G25: 82491.36 | J25: =F25-G25-H25 -> 0
A26: 46058 | B26: Şahsi | C26: Kredi | D26: Kubilay kredi | F26: 82491.36 | G26: 82491.36 | J26: =F26-G26-H26 -> 0
A27: 46086 | B27: Şahsi | C27: Kredi | D27: Kubilay kredi | F27: 83000 | G27: 83000 | J27: =F27-G27-H27 -> 0 | O27: 130 | P27: Kredi
A28: 46021 | B28: Şahsi | C28: Kart | D28: Burcin terzi kart | F28: 84000 | G28: 84000 | J28: =F28-G28-H28 -> 0 | O28: 202 | P28: Kredi
A29: 46052 | B29: Şahsi | C29: kart | D29: Burcin terzi kart | F29: 84000 | G29: 84000 | J29: =F29-G29-H29 -> 0 | O29: 100 | P29: Nexgen Kart
A30: 46081 | B30: Şahsi | C30: kart | D30: Burcin terzi kart | F30: 84000 | G30: 84000 | J30: =F30-G30-H30 -> 0 | O30: 400 | P30: Gümrük
A31: 46111 | B31: Şahsi | C31: Kart | D31: Burcin terzi kart | F31: 84000 | G31: 84000 | J31: =F31-G31-H31 -> 0 | O31: 1250 | P31: ibrahim kılıç
A32: 46142 | B32: Şahsi | C32: Kart | D32: Burcin terzi kart | F32: 84000 | J32: =F32-G32-H32 -> 84000 | O32: 250 | P32: Kart Ziraat | Q32: Altan
A33: 46172 | B33: Sahsi | C33: Kart | D33: Burcin terzi kart | F33: 84000 | J33: =F33-G33-H33 -> 84000 | O33: 1496 | P33: Dolar yapıldı
A34: 46203 | B34: Şahsi | C34: Kart | D34: Burcin terzi kart | F34: 84000 | J34: =F34-G34-H34 -> 84000
A35: 46233 | B35: Şahsi | C35: Kart | D35: Burcin terzi kart | F35: 84000 | J35: =F35-G35-H35 -> 84000
A36: 46264 | B36: Sahsi | C36: Kart | D36: Burcin terzi kart | F36: 84000 | J36: =F36-G36-H36 -> 84000 | O36: =SUBTOTAL(9,O27:O35) -> 3828
A37: 45975 | B37: Şahsi | C37: Kart | D37: Sahin Terzi Finans bank | E37: 14.11.2025 Asgari 230 bin ödendi | F37: 665000 | G37: 665000 | I37: Aktif | J37: =F37-G37-H37 -> 0
A38: 45975 | B38: Şahsi | C38: Nakit | D38: İbrahim Kılıç - Araç ödemesi | E38: Bitti | F38: 1250000 | H38: 1250000 | J38: =F38-G38-H38 -> 0 | N38: =J38 -> 0
A39: 45975 | B39: Şahsi | C39: Nakit | D39: Efsun Akyüz | E39: Bitti | F39: 70000 | G39: 70000 | J39: =F39-G39-H39 -> 0
A40: 45975 | B40: Şahsi | C40: Kart | D40: Furkan Akyüz - İbrahim in arkadaşı | E40: Bitti | F40: 500000 | G40: 300000 | H40: 200000 | J40: =F40-G40-H40 -> 0
...

Sheet Krediler
A2: Firma | B2: Tarih | C2: Kredi Adı | D2: Kalan Taksit | E2: Not | F2: Tutar | G2: Ödenen | H2: Toplam | K2: Vade | L2: Tutar | M2: Ödenen | N2: Kalan
A3: Şahin Taban | B3: 45754 | C3: Araç Alım | E3: Ford Transit | F3: =F30 -> 1825972.6 | G3: =G30 -> 1825972.6 | H3: =H30 -> 0 | J3: 2025 | K3: Ocak | L3: =SUM(F31,F34,F43,F50,F60) -> 1573241.9 | M3: =SUM(G31,G34,G43,G50,G60) -> 1573241.9 | N3: =SUM(H31,H34,H43,H50,H60) -> 0
A4: Şahin Taban | B4: 45670 | C4: Esem Işık Alımı | F4: =F33 -> 429485.5 | G4: =G33 -> 429485.5 | H4: =H33 -> 0 | J4: 2025 | K4: Şubat | L4: =SUM(F32,F35,F44,F51,F61) -> 1573241.9 | M4: =SUM(G32,G35,G44,G51,G61) -> 1573241.9 | N4: =SUM(H32,H35,H44,H51,H61) -> 0
A5: Şahin Taban | B5: 45669 | C5: Finas-iga Kredi | F5: =F42 -> 4313765.8 | G5: =G42 -> 4313765.8 | H5: =H42 -> 0 | J5: 2025 | K5: Mart | L5: =SUM(F36,F52,F62,F80) -> 1373154.2 | M5: =SUM(G36,G52,G62,G80) -> 1373154.2 | N5: =SUM(H36,H52,H62,H80) -> 0
A6: Nex-gen | B6: 45688 | C6: Nexgen Hmd | F6: =F49 -> 492440.78 | G6: =G49 -> 492440.76 | H6: =H49 -> 0.02 | J6: 2025 | K6: Nisan | L6: =SUM(F21,F37,F45,F46,F53,F63,F70,F81) -> 1870317.5 | M6: =SUM(G21,G37,G45,G46,G53,G63,G70,G81) -> 1870317.5 | N6: =SUM(H21,H37,H45,H46,H53,H63,H70,H81) -> 0
A7: Şahin Taban | B7: 45684 | C7: Lc-W ışık Alımı | F7: =F59 -> 4220701.4 | G7: =G59 -> 4220701.4 | H7: =H59 -> 0 | J7: 2025 | K7: Mayıs | L7: =SUM(F22,F38,F54,F64,F71,F82) -> 1706170.6 | M7: =SUM(G22,G38,G54,G64,G71,G82) -> 1706170.6 | N7: =SUM(H22,H38,H54,H64,H71,H82) -> 0
A8: Şahin Taban | C8: Lc-W ışık Alımı | E8: 2.Parça | F8: =F69 -> 2414143.5 | G8: =G69 -> 2414143.5 | H8: =H69 -> 0 | J8: 2025 | K8: Haziran | L8: =SUM(F23,F39,F47,F48,F55,F65,F72,F83,F107,F127) -> 2511896 | M8: =SUM(G23,G39,G47,G48,G55,G65,G72,G83,G107,G127) -> 2511896 | N8: =SUM(H23,H39,H47,H48,H55,H65,H72,H83,H107,H127) -> 0.02
A9: Şahin Taban | C9: Unicorn Patch | F9: =F79 -> 1171175.2 | G9: =G79 -> 1171175.2 | H9: =H79 -> 0 | J9: 2025 | K9: Temmuz | L9: =SUM(F24,F40,F56,F66,F73,F84,F98,F108,F115,F120,F122,F128,F124,F130,F134,F137) -> 4036957.1 | M9: =SUM(G24,G40,G56,G66,G73,G84,G98,G108,G115,G120,G122,G128,G124,G130,G134,G137) -> 4036957.1 | N9: =SUM(H24,H40,H56,H66,H73,H84,H98,H108,H115,H120,H122,H128,H124,H130,H134,H137) -> 0
A10: Şahin Taban | C10: Runix Işık | F10: =F89 -> 870556.32 | G10: =G89 -> 870556.32 | H10: =H89 -> 0 | J10: 2025 | K10: Ağustos | L10: =SUM(F25,F41,F57,F67,F74,F85,F90,F99,F109,F116,F121,F123,F125,F126,F129,F131,F135,F138) -> 4318954 | M10: =SUM(G25,G41,G57,G67,G74,G85,G90,G99,G109,G116,G121,G123,G125,G126,G129,G131,G135,G138) -> 4318954.1 | N10: =SUM(H25,H41,H57,H67,H74,H85,H90,H99,H109,H116,H121,H123,H125,H126,H129,H131,H135,H138) -> 0
A11: Şahin Taban | C11: UGG 45000 Usd Kredi | F11: =F97 -> 1713929 | G11: =G97 -> 1713929 | H11: =H97 -> 0 | J11: 2025 | K11: Eylül | L11: =SUM(F26,F58,F68,F75,F86,F91,F100,F110,F117,F132,F136,F139) -> 3415933.4 | M11: =SUM(G26,G58,G68,G75,G86,G91,G100,G110,G117,G132,G136,G139) -> 3415933.4 | N11: =SUM(H26,H58,H68,H75,H86,H91,H100,H110,H117,H132,H136,H139) -> 0
A12: Şahin Taban | C12: UGG Kuveyt Şahin tb 100.000$ kullanımın kredisi | F12: =F106 -> 4816108.5 | G12: =G106 -> 4816108.5 | H12: =H106 -> 0 | J12: 2025 | K12: Ekim | L12: =SUM(F27,F76,F87,F92,F101,F111,F118,F133,F140) -> 2451784.1 | M12: =SUM(G27,G76,G87,G92,G101,G111,G118,G133,G140) -> 2451784.1 | N12: =SUM(H27,H76,H87,H92,H101,H111,H118,H133,H140) -> 0
A13: Şahin Taban | C13: UGG Kuveyt Şahin tb kredisi | F13: =F114 -> 3924049.4 | G13: =G114 -> 3924049.4 | H13: =H114 -> 0 | J13: 2025 | K13: Kasım | L13: =SUM(F28,F77,F88,F93,F102,F112,F141) -> 1872647.7 | M13: =SUM(G28,G77,G88,G93,G102,G112,G141) -> 1872647.7 | N13: =SUM(H28,H77,H88,H93,H102,H112,H141) -> 0
A14: Şahin Taban | C14: ugg sayası için çekilen kredi | F14: =F119 -> 1878717 | G14: =G119 -> 1878717 | H14: =H119 -> 0 | J14: 2025 | K14: Aralık | L14: =SUM(F29,F78,F94,F103,F113,F142) -> 1775919.3 | M14: =SUM(G29,G78,G94,G103,G113,G142) -> 1775919.3 | N14: =SUM(H29,H78,H94,H103,H113,H142) -> 0
A15: Şahsi Krediler | C15: Kubilay - Esra -Ümit Serkan | F15: =F146 -> 2209285.4 | G15: =G146 -> 2209285.4 | H15: =H146 -> 0 | J15: 2026 | K15: Ocak | L15: =SUM(F95,F104,F143) -> 882324.34 | M15: =SUM(G95,G104,G143) -> 882324.34 | N15: =SUM(H95,H104,H143) -> 0
J16: 2026 | K16: Şubat | L16: =SUM(F96,F105,F144) -> 882324.34 | M16: =SUM(G96,G105,G144) -> 882324.34 | N16: =SUM(H96,H105,H144) -> 0
F17: =SUM(F3:F16) -> 30280330 | G17: =SUM(G3:G16) -> 30280330 | H17: =SUM(H3:H16) -> 0.02 | J17: 2026 | K17: Mart | L17: =SUM(F145) -> 35463.78 | M17: =SUM(G145) -> 35463.78 | N17: =SUM(H145) -> 0
J18: 2026 | K18: Nisan
J19: 2026 | K19: Mayıs
A20: Firma | B20: Taksit | C20: Tarih | D20: Açıklama | E20: Banka | F20: Kredi Taksidi | G20: Ödeme | H20: Kalan | J20: 2026 | K20: Haziran
A21: Şahin Taban | B21: 1.Taksit | C21: 45754 | D21: Yeni Ticari Araç | E21: Kuveytturk | F21: 202885.84 | G21: 202885.84 | H21: =F21-G21 -> 0 | J21: 2026 | K21: Temmuz
A22: Şahin Taban | B22: 2.Taksit | C22: 45784 | D22: Yeni Ticari Araç | E22: Kuveytturk | F22: 202885.84 | G22: 202885.84 | H22: =F22-G22 -> 0 | J22: 2026 | K22: Ağustos
A23: Şahin Taban | B23: 3.Taksit | C23: 45818 | D23: Yeni Ticari Araç | E23: Kuveytturk | F23: 202885.84 | G23: 202885.84 | H23: =F23-G23 -> 0 | J23: 2026 | K23: Eylül
A24: Şahin Taban | B24: 4.Taksit | C24: 45845 | D24: Yeni Ticari Araç | E24: Kuveytturk | F24: 202885.84 | G24: 202885.84 | H24: =F24-G24 -> 0 | J24: 2026 | K24: Ekim
A25: Şahin Taban | B25: 5.Taksit | C25: 45876 | D25: Yeni Ticari Araç | E25: Kuveytturk | F25: 202885.84 | G25: 202885.84 | H25: =F25-G25 -> 0 | J25: 2026 | K25: Kasım
A26: Şahin Taban | B26: 6.Taksit | C26: 45908 | D26: Yeni Ticari Araç | E26: Kuveytturk | F26: 202885.84 | G26: 202885.84 | H26: =F26-G26 -> 0 | J26: 2026 | K26: Aralık
A27: Şahin Taban | B27: 7.Taksit | C27: 45937 | D27: Yeni Ticari Araç | E27: Kuveytturk | F27: 202885.84 | G27: 202885.84 | H27: =F27-G27 -> 0
A28: Şahin Taban | B28: 8.Taksit | C28: 45968 | D28: Yeni Ticari Araç | E28: Kuveytturk | F28: 202885.84 | G28: 202885.84 | H28: =F28-G28 -> 0
A29: Şahin Taban | B29: 9.Taksit | C29: 45999 | D29: Yeni Ticari Araç | E29: Kuveytturk | F29: 202885.92 | G29: 202885.92 | H29: =F29-G29 -> 0 | L29: =SUBTOTAL(9,L3:L18) -> 30280330 | M29: =SUBTOTAL(9,M3:M18) -> 30280330 | N29: =SUBTOTAL(9,N3:N18) -> 0.02
F30: =SUM(F21:F29) -> 1825972.6 | G30: =SUM(G21:G29) -> 1825972.6 | H30: =SUM(H21:H29) -> 0
A31: Şahin Taban | B31: 5.Taksit | C31: 45670 | D31: Işık | E31: Kuveytturk | F31: 214742.76 | G31: 214742.76 | H31: =F31-G31 -> 0
A32: Şahin Taban | B32: 6.Taksit | C32: 45701 | D32: Işık | E32: Kuveytturk | F32: 214742.74 | G32: 214742.74 | H32: =F32-G32 -> 0
F33: =SUM(F31:F32) -> 429485.5 | G33: =SUM(G31:G32) -> 429485.5 | H33: =SUM(H31:H32) -> 0
A34: Şahin Taban | B34: 5.Taksit | C34: 45669 | D34: İga Kredi | E34: Finansbank | F34: 539220.73 | G34: 539220.73 | H34: =F34-G34 -> 0
A35: Şahin Taban | B35: 6.Taksit | C35: 45700 | D35: İga Kredi | E35: Finansbank | F35: 539220.73 | G35: 539220.73 | H35: =F35-G35 -> 0
A36: Şahin Taban | B36: 7.Taksit | C36: 45728 | D36: İga Kredi | E36: Finansbank | F36: 539220.73 | G36: 539220.73 | H36: =F36-G36 -> 0
A37: Şahin Taban | B37: 8.Taksit | C37: 45759 | D37: İga Kredi | E37: Finansbank | F37: 539220.73 | G37: 539220.73 | H37: =F37-G37 -> 0
A38: Şahin Taban | B38: 9.Taksit | C38: 45789 | D38: İga Kredi | E38: Finansbank | F38: 539220.73 | G38: 539220.73 | H38: =F38-G38 -> 0
A39: Şahin Taban | B39: 10.Taksit | C39: 45820 | D39: İga Kredi | E39: Finansbank | F39: 539220.73 | G39: 539220.73 | H39: =F39-G39 -> 0
A40: Şahin Taban | B40: 11.Taksit | C40: 45850 | D40: İga Kredi | E40: Finansbank | F40: 539220.73 | G40: 539220.73 | H40: =F40-G40 -> 0
A41: Şahin Taban | B41: 12.Taksit | C41: 45881 | D41: İga Kredi | E41: Finansbank | F41: 539220.7 | G41: 539220.73 | H41: 0
...

Sheet Krediler (2)
A2: Firma | B2: Tarih | C2: Kredi Adı | D2: Kalan Taksit | E2: Not | F2: Tutar | G2: Ödenen | H2: Toplam | K2: Vade | L2: Tutar | M2: Ödenen | N2: Kalan
A3: Şahin Taban | B3: 45931 | C3: =D21 -> Nakit İhtiyacı | F3: =F30 -> 2970000 | G3: =G30 -> 330000 | H3: =H30 -> 2640000 | J3: 2025 | K3: Ekim | L3: =F61 -> 266081.7 | M3: =G61 -> 266081.7 | N3: =H61 -> 0
A4: Şahin Taban | B4: 45931 | C4: =D31 -> Nakit İhtiyacı - 2 | F4: =F40 -> 329999.94 | G4: =G40 -> 36666.66 | H4: =H40 -> 293333.28 | J4: 2025 | K4: Kasım | L4: =F62 -> 266081.7 | M4: =G62 -> 266081.7 | N4: =H62 -> 0
A5: Şahin Taban | B5: 45931 | C5: =D41 -> Nakit İhtiyacı - 3 | F5: =F50 -> 1724999.9 | G5: =G50 -> 191666.66 | H5: =H50 -> 1533333.3 | J5: 2025 | K5: Aralık | L5: =SUM(F63,F84) -> 1047748.6 | M5: =SUM(G63,G84) -> 1047748.6 | N5: =SUM(H63,H84) -> 0
A6: Şahin Taban | B6: 45931 | C6: =D51 -> Nakit İhtiyacı - 4 | F6: =F60 -> 2000000 | G6: =G60 -> 444444.44 | H6: =H60 -> 1555555.5 | J6: 2026 | K6: Ocak | L6: =SUM(F64,F85) -> 1047748.6 | M6: =SUM(G64,G85) -> 1047748.6 | N6: =SUM(H64,H85) -> 0
A7: Şahin Taban | B7: 45931 | C7: =D61 -> KGF Nakit İhtiyacı | F7: =F73 -> 3192980.4 | G7: =G73 -> 1862571.9 | H7: =H73 -> 1330408.5 | J7: 2026 | K7: Şubat | L7: =SUM(F51,F65,F74,F86) -> 2132008.1 | M7: =SUM(G51,G65,G74,G86) -> 2132007.6 | N7: =SUM(H51,H65,H74,H86) -> 0.5
A8: Şahin Taban | B8: 45931 | C8: =D80 -> Patch - ışık - Kalıp | F8: =F83 -> 7758335.7 | G8: =G83 -> 1724074.6 | H8: =H83 -> 6034261.1 | J8: 2026 | K8: Mart | L8: =SUM(F21,F31,F41,F52,F66,F75,F87) -> 2690341.4 | M8: =SUM(G21,G31,G41,G52,G66,G75,G87) -> 2690341.4 | N8: =SUM(H21,H31,H41,H52,H66,H75,H87) -> 0
C9: =D84 -> Kgf Kredisi | F9: =F96 -> 9380002.6 | G9: =G96 -> 3126667 | H9: =H96 -> 6253335.6 | J9: 2026 | K9: Nisan | L9: =SUM(F22,F32,F42,F53,F67,F76,F88) -> 2690341.4 | M9: =SUM(G22,G32,G42,G53,G67,G76,G88) -> 266081.7 | N9: =SUM(H22,H32,H42,H53,H67,H76,H88) -> 2424259.7
J10: 2026 | K10: Mayıs | L10: =SUM(F23,F33,F43,F54,F68,F77,F89) -> 2690341.4 | M10: =SUM(G23,G33,G43,G54,G68,G77,G89) -> 0 | N10: =SUM(H23,H33,H43,H54,H68,H77,H89) -> 2690341.4
J11: 2026 | K11: Haziran | L11: =SUM(F24,F34,F44,F55,F69,F78,F90) -> 2690341.4 | M11: =SUM(G24,G34,G44,G55,G69,G78,G90) -> 0 | N11: =SUM(H24,H34,H44,H55,H69,H78,H90) -> 2690341.4
J12: 2026 | K12: Temmuz | L12: =SUM(F25,F35,F45,F56,F70,F79,F91) -> 2690341.4 | M12: =SUM(G25,G35,G45,G56,G70,G79,G91) -> 0 | N12: =SUM(H25,H35,H45,H56,H70,H79,H91) -> 2690341.4
J13: 2026 | K13: Ağustos | L13: =SUM(F26,F36,F46,F57,F71,F80,F92) -> 2690341.4 | M13: =SUM(G26,G36,G46,G57,G71,G80,G92) -> 0 | N13: =SUM(H26,H36,H46,H57,H71,H80,H92) -> 2690341.4
J14: 2026 | K14: Eylül | L14: =SUM(F27,F37,F47,F58,F72,F81,F93) -> 2690341.4 | M14: =SUM(G27,G37,G47,G58,G72,G81,G93) -> 0 | N14: =SUM(H27,H37,H47,H58,H72,H81,H93) -> 2690341.4
J15: 2026 | K15: Ekim | L15: =SUM(F28,F38,F48,F59,F82,F94) -> 2424259.7 | M15: =SUM(G28,G38,G48,G59,G82,G94) -> 0 | N15: =SUM(H28,H38,H48,H59,H82,H94) -> 2424259.7
J16: 2026 | K16: Kasım | L16: =SUM(F29,F39,F49,F95) -> 1340000.2 | M16: =SUM(G29,G39,G49,G95) -> 0 | N16: =SUM(H29,H39,H49,H95) -> 1340000.2
F17: =SUM(F3:F16) -> 27356319 | G17: =SUM(G3:G16) -> 7716091.3 | H17: =SUM(H3:H16) -> 19640227 | J17: 2026 | K17: Aralık
K19: Durum Kredi2 | L19: =SUM(L3:L18) -> 27356319 | M19: =SUM(M3:M18) -> 7716091.3 | N19: =SUM(N3:N18) -> 19640227
A20: Firma | B20: Taksit | C20: Tarih | D20: Açıklama | E20: Banka | F20: Kredi Taksidi | G20: Ödeme | H20: Kalan
A21: Şahin Taban | B21: 1.Taksit | C21: 46112 | D21: Nakit İhtiyacı | E21: Kuveytturk | F21: 330000 | G21: 330000 | H21: =F21-G21 -> 0
A22: Şahin Taban | B22: 2.Taksit | C22: 46142 | D22: Nakit İhtiyacı | E22: Kuveytturk | F22: 330000 | H22: =F22-G22 -> 330000
A23: Şahin Taban | B23: 3.Taksit | C23: 46173 | D23: Nakit İhtiyacı | E23: Kuveytturk | F23: 330000 | H23: =F23-G23 -> 330000
A24: Şahin Taban | B24: 4.Taksit | C24: 46203 | D24: Nakit İhtiyacı | E24: Kuveytturk | F24: 330000 | H24: =F24-G24 -> 330000
A25: Şahin Taban | B25: 5.Taksit | C25: 46234 | D25: Nakit İhtiyacı | E25: Kuveytturk | F25: 330000 | H25: =F25-G25 -> 330000
A26: Şahin Taban | B26: 6.Taksit | C26: 46265 | D26: Nakit İhtiyacı | E26: Kuveytturk | F26: 330000 | H26: =F26-G26 -> 330000
A27: Şahin Taban | B27: 7.Taksit | C27: 46295 | D27: Nakit İhtiyacı | E27: Kuveytturk | F27: 330000 | H27: =F27-G27 -> 330000
A28: Şahin Taban | B28: 8.Taksit | C28: 46326 | D28: Nakit İhtiyacı | E28: Kuveytturk | F28: 330000 | H28: =F28-G28 -> 330000
A29: Şahin Taban | B29: 9.Taksit | C29: 46356 | D29: Nakit İhtiyacı | E29: Kuveytturk | F29: 330000 | H29: =F29-G29 -> 330000
F30: =SUM(F21:F29) -> 2970000 | G30: =SUM(G21:G29) -> 330000 | H30: =SUM(H21:H29) -> 2640000
A31: Şahin Taban | B31: 1.Taksit | C31: 46112 | D31: Nakit İhtiyacı - 2 | E31: Kuveytturk | F31: 36666.66 | G31: 36666.66 | H31: =F31-G31 -> 0
A32: Şahin Taban | B32: 2.Taksit | C32: 46142 | D32: Nakit İhtiyacı - 2 | E32: Kuveytturk | F32: 36666.66 | H32: =F32-G32 -> 36666.66
A33: Şahin Taban | B33: 3.Taksit | C33: 46173 | D33: Nakit İhtiyacı - 2 | E33: Kuveytturk | F33: 36666.66 | H33: =F33-G33 -> 36666.66
A34: Şahin Taban | B34: 4.Taksit | C34: 46203 | D34: Nakit İhtiyacı - 2 | E34: Kuveytturk | F34: 36666.66 | H34: =F34-G34 -> 36666.66
A35: Şahin Taban | B35: 5.Taksit | C35: 46234 | D35: Nakit İhtiyacı - 2 | E35: Kuveytturk | F35: 36666.66 | H35: =F35-G35 -> 36666.66
A36: Şahin Taban | B36: 6.Taksit | C36: 46265 | D36: Nakit İhtiyacı - 2 | E36: Kuveytturk | F36: 36666.66 | H36: =F36-G36 -> 36666.66
A37: Şahin Taban | B37: 7.Taksit | C37: 46295 | D37: Nakit İhtiyacı - 2 | E37: Kuveytturk | F37: 36666.66 | H37: =F37-G37 -> 36666.66
A38: Şahin Taban | B38: 8.Taksit | C38: 46326 | D38: Nakit İhtiyacı - 2 | E38: Kuveytturk | F38: 36666.66 | H38: =F38-G38 -> 36666.66
A39: Şahin Taban | B39: 9.Taksit | C39: 46356 | D39: Nakit İhtiyacı - 2 | E39: Kuveytturk | F39: 36666.66 | H39: =F39-G39 -> 36666.66
F40: =SUM(F31:F39) -> 329999.94 | G40: =SUM(G31:G39) -> 36666.66 | H40: =SUM(H31:H39) -> 293333.28
A41: Şahin Taban | B41: 1.Taksit | C41: 46083 | D41: Nakit İhtiyacı - 3 | E41: Kuveytturk | F41: 191666.66 | G41: 191666.66 | H41: =F41-G41 -> 0
A42: Şahin Taban | B42: 2.Taksit | C42: 46114 | D42: Nakit İhtiyacı - 3 | E42: Kuveytturk | F42: 191666.66 | H42: =F42-G42 -> 191666.66
...

Sheet Çekler
A1: Şahin Taban | B1: 45960 | C1: Nexgen Kimya | D1: 14913 | E1: 100000 | F1: 100000 | G1: =E1-F1 -> 0 | H1: 2025 | I1: Ekim | J1: =SUM(E1,E2,E3,E4,E5) -> 719668.25 | K1: =SUM(F1,F2,F3,F4,F5) -> 719668.25 | L1: =SUM(G1,G2,G3,G4,G5) -> 0
A2: Şahin Taban | B2: 45960 | C2: Orbital Yazılım | D2: 379202 | E2: 120000 | F2: 120000 | G2: =E2-F2 -> 0 | H2: 2025 | I2: Kasım | J2: =SUM(E6,E7,E8) -> 440000 | K2: =SUM(F6,F7,F8) -> 440000 | L2: =SUM(G6,G7,G8) -> 0
A3: Şahin Taban | B3: 45961 | C3: Demirel Oluklu Mukavva | D3: 7021617 | E3: 74668.25 | F3: 74668.25 | G3: =E3-F3 -> 0 | H3: 2025 | I3: Aralık | J3: =SUM(E9,E10,E11) -> 939967.07 | K3: =SUM(F9,F10,F11) -> 939967.07 | L3: =SUM(G9,G10,G11) -> 0
A4: Şahin Taban | B4: 45961 | C4: Altuğ Kimya | D4: 379204 | E4: 200000 | F4: 200000 | G4: =E4-F4 -> 0 | H4: 2026 | I4: Ocak | J4: =SUM(E12,E13,E14) -> 1458943.1 | K4: =SUM(F12,F13,F14) -> 1458943.1 | L4: =SUM(G12,G13,G14) -> 0
A5: Şahin Taban | B5: 45961 | C5: Nexgen Kimya | D5: 7021620 | E5: 225000 | F5: 225000 | G5: =E5-F5 -> 0 | H5: 2026 | I5: Şubat | J5: =SUM(E15,E16,E17) -> 912505 | K5: =SUM(F15,F16,F17) -> 912505 | L5: =SUM(G15,G16,G17) -> 0
A6: Şahin Taban | B6: 45989 | C6: Nexgen Kimya | D6: 7021618 | E6: 225000 | F6: 225000 | G6: =E6-F6 -> 0 | H6: 2026 | I6: Mart | J6: 526997.6 | K6: 526997.6 | L6: 0
A7: Şahin Taban | B7: 45991 | C7: Mehmet Kurt (Stıkır ) | D7: 0379208 | E7: 100000 | F7: 100000 | G7: =E7-F7 -> 0 | H7: 2026 | I7: Nisan | J7: 699686.04 | K7: =SUM(F19,F20,F21) -> 26997.6 | L7: 699686.04
A8: Şahin Taban | B8: 45991 | C8: Nexgen Kimya | D8: 14914 | E8: 115000 | F8: 115000 | G8: =E8-F8 -> 0 | H8: 2026 | I8: Mayıs | J8: 777180 | K8: =SUM(F22,F23) -> 0 | L8: 777180
A9: Şahin Taban | B9: 46006 | C9: Kısmet Ayakkabı Yan San. ve Tic A.Ş | D9: 7021623 | E9: 381024 | F9: 381024 | G9: =E9-F9 -> 0 | H9: 2026 | I9: Haziran | J9: 685349.24 | K9: =SUM(F24,F25,F26) -> 0 | L9: 685349.24
A10: Şahin Taban | B10: 46022 | C10: Mehmet Kurt (Stıkır ) | D10: 0379209 | E10: 100000 | F10: 100000 | G10: =E10-F10 -> 0 | H10: 2026 | I10: Temmuz | J10: 757571 | K10: =SUM(F27,F28,F29) -> 0 | L10: 757571
A11: Şahin Taban | B11: 46022 | C11: Gros Foam | D11: 0014909 | E11: 458943.07 | F11: 458943.07 | G11: =E11-F11 -> 0 | H11: 2026 | I11: Ağustos | J11: 657799.42 | K11: =SUM(F30) -> 0 | L11: 657799.42
A12: Şahin Taban | B12: 46053 | C12: Gros Foam | D12: 0014910 | E12: 458943.07 | F12: 458943.07 | G12: =E12-F12 -> 0 | H12: 2026 | I12: Eylül | J12: 700000 | K12: 0 | L12: 700000
A13: Şahin Taban | B13: 46053 | C13: As Aras Turizm - Servis | D13: 7021621 | E13: 500000 | F13: 500000 | G13: =E13-F13 -> 0 | H13: 2026 | I13: Ekim | J13: 500000 | K13: 0 | L13: 500000
A14: Şahin Taban | B14: 46053 | C14: Nexgen Kimya San.ve Tic.Ltd.Şti | D14: 14915 | E14: 500000 | F14: 500000 | G14: =E14-F14 -> 0 | H14: 2026 | I14: Kasım | J14: 250000 | K14: 0 | L14: 250000
A15: Şahin Taban | B15: 46081 | C15: Mehmet Kurt (Stıkır ) | D15: 0379210 | E15: 200000 | F15: 200000 | G15: =E15-F15 -> 0 | H15: 2026 | I15: Aralık | J15: 0 | K15: 0
A16: Şahin Taban | B16: 46081 | C16: Nexgen Kimya | D16: 7021619 | E16: 500000 | F16: 500000 | G16: =E16-F16 -> 0 | J16: 0 | K16: 0
A17: Şahin Taban | B17: 46081 | C17: Kısmet Ticaret | D17: 0383262 | E17: 212505 | F17: 212505 | G17: =E17-F17 -> 0
A18: Şahin Taban | B18: 46112 | C18: As Aras Turizm - Servis | D18: 0379211 | E18: 500000 | F18: 500000 | G18: =E18-F18 -> 0 | J18: 0 | K18: 0
A19: Sahin Taban | B19: 46112 | C19: Nexgen Kimya San.ve Tic.Ltd.Şti | D19: 0383267 | E19: 26997.6 | F19: 26997.6 | G19: =E19-F19 -> 0
A20: Şahin Taban | B20: 46142 | C20: Viyolet Matbaa Etiket-Ömer Aksu | D20: 0383257 | E20: 400000 | G20: =E20-F20 -> 400000
A21: Şahin Taban | B21: 46142 | C21: Pera | D21: 0383253 | E21: 74905.8 | G21: =E21-F21 -> 74905.8
A22: Şahin Taban | B22: 46142 | C22: Polimer Ambalaj -Doğan Sağlam | D22: 0383261 | E22: 75000 | G22: =E22-F22 -> 75000
A23: Sahin Taban | B23: 46142 | C23: Nexgen Kimya San.ve Tic.Ltd.Şti | D23: 0383263 | E23: 149780.24 | G23: =E23-F23 -> 149780.24
A24: Şahin Taban | B24: 46173 | C24: Doğan Plastik Sanayi-Aşkın Arslan | D24: 0379212 | E24: 540000 | G24: =E24-F24 -> 540000
A25: Şahin Taban | B25: 46173 | C25: Polimer Ambalaj -Doğan Sağlam | D25: 0383260 | E25: 75000 | G25: =E25-F25 -> 75000
A26: Sahin Taban | B26: 46173 | C26: Nexgen Kimya San.ve Tic.Ltd.Şti | D26: 0383264 | E26: 162180 | G26: =E26-F26 -> 162180
A27: Şahin Taban | B27: 46203 | C27: Pera | D27: 7021622 | E27: 210117 | G27: =E27-F27 -> 210117
A28: Şahin Taban | B28: 46203 | C28: Altuğ kimya Tekstil Sanayi ve Ticaret Ltd Şti | D28: 7021625 | E28: 200000 | G28: =E28-F28 -> 200000
A29: Şahin Taban | B29: 46203 | C29: Nexgen Kimya San.ve Tic.Ltd.Şti | D29: 0383258 | E29: 100000 | G29: =E29-F29 -> 100000
A30: Sahin Taban | B30: 46203 | C30: Guney Rulman | D30: 0383258 | E30: 100000 | G30: =E30-F30 -> 100000
A31: Sahin Taban | B31: 46203 | C31: Nexgen Kimya San ve Tic.Ltd.Sti | D31: 0381258 | E31: 75232.24 | G31: =E31-F31 -> 75232.24
... A34: Şahin Taban | B34: 46234 | C34: MAGDEBURGER SİGORTA A.Ş. | D34: 0383259 | E34: 250000 | G34: =E34-F34 -> 250000
A35: Sahin Taban | B35: 46264 | C35: Guney Rulman | D35: 383265 | E35: 175000 | G35: =E35-F35 -> 175000
A36: Şahin Taban | B36: 46265 | C36: Pera A.s | D36: 0383254 | E36: 232799.42 | G36: =E36-F36 -> 232799.42
A37: Sahin Taban | B37: 46265 | C37: Viyolet Matbaa Etiket-Ömer Aksu | D37: 0381259 | E37: 250000 | G37: =E37-F37 -> 250000
A38: Sahin Taban | B38: 46295 | C38: Viyolet Matbaa Etiket-Ömer Aksu | D38: 381260 | E38: 500000 | G38: =E38-F38 -> 500000
A39: Sahin Taban | B39: 46295 | C39: FTS Fuarcilik sanat etkinlikleri | D39: 381262 | E39: 200000 | G39: =E39-F39 -> 200000
A40: Sahin Taban | B40: 46326 | C40: Viyolet Matbaa Etiket-Ömer Aksu | D40: 381261 | E40: 250000 | G40: =E40-F40 -> 250000
A41: Sahin Taban | B41: 46326 | C41: YON Ayakkabi Malzemeleri | D41: 381263 | E41: 250000 | G41: =E41-F41 -> 250000
A42: Sahin Taban | B42: 31.11.2026 | C42: YON Ayakkabi Malzemeleri | D42: 381263 | E42: 250000 | G42: =E42-F42 -> 250000
...

Sheet Extra
A2: Firma | B2: Vade Tarihi | C2: Verilen Cari | D2: Tutar USD | E2: Kur | F2: Tutar | G2: Ödenen | H2: Kalan | J2: Vade | K2: Tutar | L2: Ödenen | M2: Kalan
A3: Nexgen | B3: 45856 | C3: Fiona - Çin | D3: 27170 | E3: 39.6 | F3: =D3*E3 -> 1075932 | G3: 1075932 | H3: =F3-G3 -> 0 | I3: 2025 | J3: Haziran | K3: 0 | L3: 0 | M3: 0
A4: Nexgen | B4: 20-25.08.2025 | C4: Fiona - Çin | D4: 21000 | E4: 39.6 | F4: =D4*E4 -> 831600 | G4: 831600 | H4: =F4-G4 -> 0 | I4: 2025 | J4: Temmuz | K4: =SUM(F3+F12) -> 2075932 | L4: =SUM(G3+G12) -> 2075932 | M4: =SUM(H3+H12) -> 0
A5: Nexgen | B5: 45991 | C5: Fiona - Çin | D5: 40000 | E5: 42.4 | F5: =D5*E5 -> 1696000 | G5: 1696000 | H5: =F5-G5 -> 0 | I5: 2025 | J5: Ağustos | K5: =SUM(F4,F9,F13,F14) -> 6831600 | L5: =SUM(G4,G9,G13,G14) -> 6831600 | M5: =SUM(H4,H9,H13,H14) -> 0
A6: Nexgen | B6: 46011 | C6: Fiona - Çin | D6: 44088 | E6: 42.7 | F6: =D6*E6 -> 1882557.6 | G6: 1882557.6 | H6: =F6-G6 -> 0 | I6: 2025 | J6: Eylül | K6: =SUM(F10) -> 4000000 | L6: =SUM(G10) -> 4000000 | M6: =SUM(H10) -> 0
I7: 2025 | J7: Ekim | K7: =SUM(F11) -> 4000000 | L7: =SUM(G11) -> 4000000 | M7: =SUM(H11) -> 0
I8: 2025 | J8: Kasım | K8: =SUM(F5) -> 1696000 | L8: =SUM(G5) -> 1696000 | M8: =SUM(H5) -> 0
A9: Şahin Taban | B9: 45889 | C9: Lc-W Ugg Avans Kesinti 1/3 | D9: 4000000 | E9: 1 | F9: =D9*E9 -> 4000000 | G9: =E9*F9 -> 4000000 | H9: =F9-G9 -> 0 | I9: 2025 | J9: Aralık | K9: =SUM(F6) -> 1882557.6 | L9: =SUM(G6) -> 1882557.6 | M9: =SUM(H6) -> 0
A10: Şahin Taban | B10: 45920 | C10: Lc-W Ugg Avans Kesinti 2/3 | D10: 4000000 | E10: 1 | F10: =D10*E10 -> 4000000 | G10: =E10*F10 -> 4000000 | H10: =F10-G10 -> 0 | I10: 2026 | J10: Ocak | K10: =SUM(F16) -> 3300000 | L10: =SUM(G16) -> 3300000 | M10: =SUM(H16) -> 0
A11: Şahin Taban | B11: 45950 | C11: Lc-W Ugg Avans Kesinti 3/3 | D11: 4000000 | E11: 1 | F11: =D11*E11 -> 4000000 | G11: =E11*F11 -> 4000000 | H11: =F11-G11 -> 0 | I11: 2026 | J11: Şubat | K11: =SUM(F17) -> 3300000 | L11: =SUM(G17) -> 3300000 | M11: =SUM(H17) -> 0
A12: Şahin Taban | B12: 45862 | C12: Ugg Konteyner 2 - Nakliye ödeme | D12: 1000000 | E12: 1 | F12: =D12*E12 -> 1000000 | G12: =E12*F12 -> 1000000 | H12: =F12-G12 -> 0 | I12: 2026 | J12: Mart | K12: =SUM(F18) -> 3300000 | L12: =SUM(G18) -> 3300000 | M12: =SUM(H18) -> 0
A13: Şahin Taban | B13: 45884 | C13: Ugg Konteyner 1 - Nakliye ödeme | D13: 1000000 | E13: 1 | F13: =D13*E13 -> 1000000 | G13: =E13*F13 -> 1000000 | H13: =F13-G13 -> 0 | I13: 2026 | J13: Nisan | K13: =SUM(F19) -> 3300000 | L13: =SUM(G19) -> 0 | M13: =SUM(H19) -> 3300000
A14: Şahin Taban | B14: 45894 | C14: Ugg Konteyner 3 - Nakliye ödeme | D14: 1000000 | E14: 1 | F14: =D14*E14 -> 1000000 | G14: =E14*F14 -> 1000000 | H14: =F14-G14 -> 0 | I14: 2026 | J14: Mayıs | K14: =SUM(F20) -> 3300000 | L14: =SUM(G20) -> 0 | M14: =SUM(H20) -> 3300000
I15: 2026 | J15: Haziran | K15: =SUM(F21) -> 0 | L15: =SUM(G21) -> 0 | M15: =SUM(H21) -> 0
A16: Şahin Taban | B16: 46042 | C16: Lc-W Işık Patch Avans Kesinti 1/6 | D16: 3300000 | E16: 1 | F16: 3300000 | G16: 3300000 | H16: =F16-G16 -> 0 | I16: 2026 | J16: Temmuz | K16: =SUM(F22) -> 0 | L16: =SUM(G22) -> 0 | M16: =SUM(H22) -> 0
A17: Şahin Taban | B17: 46073 | C17: Lc-W Işık Patch Avans Kesinti 2/6 | D17: 3300000 | E17: 1 | F17: 3300000 | G17: 3300000 | H17: =F17-G17 -> 0 | Q17: =SUM(D16:D20)/6 -> 2750000
A18: Şahin Taban | B18: 46101 | C18: Lc-W Işık Patch Avans Kesinti 3/6 | D18: 3300000 | E18: 1 | F18: 3300000 | G18: 3300000 | H18: =F18-G18 -> 0
A19: Şahin Taban | B19: 46132 | C19: Lc-W Işık Patch Avans Kesinti 4/6 | D19: 3300000 | E19: 1 | F19: 3300000 | G19: 0 | H19: =F19-G19 -> 3300000
A20: Şahin Taban | B20: 46162 | C20: Lc-W Işık Patch Avans Kesinti 5/6 | D20: 3300000 | E20: 1 | F20: 3300000 | G20: 0 | H20: =F20-G20 -> 3300000
K24: =SUBTOTAL(9,K3:K18) -> 36986090 | L24: =SUBTOTAL(9,L3:L18) -> 30386090 | M24: =SUBTOTAL(9,M3:M18) -> 6600000
F26: =SUM(F3:F25) -> 36986090 | G26: =SUM(G3:G25) -> 30386090 | H26: =SUM(H3:H25) -> 6600000

Sheet Ödeme Tablo
A3: Tarih | B3: Birim | C3: MALZEMENİN CİNSİ | D3: ÖDEME | E3: TUTARI | F3: Ödenen Tutar | G3: Bakiye | H3: Not | I3: Kasa | J3: =G41 -> 0
A4: 46113 | B4: Cari Odeme | C4: Dmt Lc | E4: 50000 | F4: 50000 | G4: =D4+G4+F4-D4 -> 0
A5: 46113 | B5: Masraf | C5: 34 BPY 282 Plaka Noter | E5: 420 | F5: 420 | G5: =G5+F5-D5 -> 0
A6: 46113 | B6: Masraf | C6: 34 BPY 282 Plaka Soforler odasi | E6: 850 | F6: 850 | G6: =G6+F6-D6 -> 0
A7: 46113 | B7: Masraf | C7: Sanayi Odasi | E7: 3300 | F7: 3300 | G7: =G7+F7-D7 -> 0
A8: 46113 | B8: Masraf | C8: Eva Personel Prim | E8: 14500 | F8: 14500 | G8: =G8+F8-D8 -> 0
A9: 46113 | B9: Masraf | C9: Personel Avans | E9: 10000 | F9: 10000 | G9: =G9+F9-D9 -> 0
A10: 46114 | B10: Kredi | C10: Kuveytturk Nexgen | E10: 192000 | F10: 192000 | G10: =G10+F10-D10 -> 0
A11: 46114 | B11: Borc | C11: Kubilay Gurbuz | E11: 1320000 | F11: 1320000 | G11: =G10+#REF!-D11 -> 0
A12: 46114 | B12: Cari Odeme | C12: Altarnatif Kimya tpo holment 100m | E12: 5150 | F12: 5150 | G12: =G11+F12-D12 -> 0
A13: 46114 | B13: Cari Odeme | C13: Meram Dar dokuma | E13: 40080 | F13: 40080 | G13: =G12+F13-D13 -> 0
A14: 46114 | B14: Cin | C14: Vize icin turgay Vatansever | E14: 15600 | F14: 15600 | G14: =G13+F14-D14 -> 0
A15: 46115 | B15: Maas | C15: 1 ay mastan kalan | E15: 285000 | F15: 285000 | G15: =G14+F15-D15 -> 0
A16: 46115 | B16: Kredi Karti | C16: Sahin terzi finansbank kart | E16: 220000 | F16: 0 | G16: =G15+F16-D16 -> 0
A17: 46115 | B17: Kredi Karti | C17: Sevgi terzi | E17: 253000 | F17: 253000 | G17: =G16+F17-D17 -> 0
A18: 46115 | B18: Kredi Karti | C18: Metin tuncer | E18: 380000 | F18: 0 | G18: =G17+F18-D18 -> 0
A19: 46115 | B19: Cin | C19: Star conteyner | E19: 27000 | F19: 27000 | G19: =G18+F19-D19 -> 0
A20: 46115 | B20: kmh | C20: nebi tecer alindi | E20: 30000 | F20: 30000 | G20: =G19+F20-D20 -> 0
A21: 46115 | B21: KASA | C21: LCW gelen odeme | D21: 1150000 | E21: 0 | F21: 0 | G21: =G20+F21-D21 -> 0
A22: 46115 | B22: Cari Odeme | C22: Most Event turizm | E22: 36300 | F22: 36300 | G22: =G21+F22-D22 -> 0
A23: 46118 | B23: KASA | C23: LCW gelen odeme | D23: 684263.36 | G23: =G23+F23-D23 -> 0
A24: 46118 | B24: Cari Odeme | C24: Arabulcuk hizmeti ulku cetok | E24: 9000 | F24: 9000 | G24: =G24+F24-D24 -> 0
A25: 46118 | B25: Devlet | C25: imzsa sulkusu sahin taban | E25: 25000 | F25: 25000 | G25: =G24+F25-D25 -> 0
A26: 46118 | B26: Vergi | C26: Ithalat Beyhannamesi | E26: 136889.92 | F26: 136889.92 | G26: =G25+F26-D26 -> 0
A27: 46118 | B27: Cari Odeme | C27: Family Cevre Sahin , Nexgen | E27: 12000 | F27: 12000 | G27: =G26+F27-D27 -> 0
A28: 46118 | B28: Cari Odeme | C28: Sayaci Gazi | G28: =G27+F28-D28 -> 0
A29: 46118 | B29: Cari Odeme | C29: Saya OTOMAT | E29: 50000 | F29: 50000 | G29: =G28+F29-D29 -> 0
A30: 46120 | B30: Kredi Karti | C30: Altan Terzi Garanti Sgk | E30: 457000 | F30: 457000 | G30: =G29+F30-D30 -> 0
A31: 46120 | B31: Cari Odeme | C31: Aymet makina | E31: 4500 | F31: 4500 | G31: =G30+F31-D31 -> 0
A32: 46120 | B32: Cari Odeme | C32: Pera baca icin yapilan odeme | E32: 5000 | F32: 5000 | G32: =G31+F32-D32 -> 0
A33: 46120 | B33: Avans | C33: Erhan Fethi atlar | E33: 10000 | F33: 10000 | G33: =G32+F33-D33 -> 0
A34: 46120 | B34: KASA | C34: LCW gelen odeme | D34: 4500000
A35: 46121 | B35: KASA | C35: Flo Gelen odeme | D35: 296673.92
A36: 46122 | B36: Cari Odeme | C36: Pdl yag Nexgen Kimya | E36: 740000 | F36: 0 | G36: =G36+F36-D36 -> 0 | I36: Not 16609$ Karsiligi Odeme yapilcak
A37: 46122 | B37: Kmh | C37: Sinan ates | E37: 120000 | F37: 0 | G37: =G37+F37-D37 -> 0
A38: 46122 | B38: Avans | C38: Muhasebe Resul Bey Avans talebi | E38: 50000 | F38: 50000 | G38: =G37+F38-D38 -> 0
A39: 46122 | B39: Maas | C39: Sahin Taban Elden | E39: 3430000 | F39: 3430000 | G39: =G38+F39-D39 -> 0
A40: 46122 | B40: Maas | C40: Sahin Taban Banka | E40: 2334000 | F40: 2234000 | G40: =G39+F40-D40 -> 0
A41: 46122 | B41: Maas | C41: Nexgen Banka | E41: 213829.63 | F41: 213829.63 | G41: =G40+F41-D41 -> 0
A42: 46122 | B42: Maas | C42: Nexgen Elden | E42: 88360.4 | F42: 88360 | G42: =G41+F42-D42 -> 0
...

Sheet Özet Tablo
B2: 2026 | C2: 2026 | D2: 2026 | E2: 2026 | F2: 2026 | G2: 2026 | H2: 2026 | I2: 2026 | J2: 2026 | K2: 2026 | L2: 2026 | M2: 2026 | N2: Toplamlar
A3: Vade | B3: Ocak | C3: Şubat | D3: Mart | E3: Nisan | F3: Mayıs | G3: Haziran | H3: Temmuz | I3: Ağustos | J3: Eylül | K3: Ekim | L3: Kasım | M3: Aralık
A4: Gayri Resmi Borçlanma | B4: 0 | C4: 1000000 | D4: 1000000 | E4: 1000000 | F4: 1000000 | G4: 1000000 | H4: 1000000 | I4: 1000000 | J4: 0 | K4: 0 | L4: 0 | M4: 0 | N4: =SUM(B4:M4) -> 7000000
A5: Extra Ödemeler Avans - Nakit | B5: =Extra!I34 -> 0 | C5: =Durum!F4 -> 0 | D5: =Durum!F5 -> 0 | E5: =Durum!F6 -> 3300000 | F5: =Durum!F7 -> 3300000 | G5: =Durum!IF8 -> 0 | H5: =Extra!O34 -> 0 | I5: =Extra!P34 -> 0 | J5: =Extra!Q34 -> 0 | K5: =Extra!R34 -> 0 | L5: =Extra!S34 -> 0 | M5: =Extra!T34 -> 0 | N5: =SUM(B5:M5) -> 6600000
A6: Genel Gider - Nakit Maaş Dahil (Yaklaşık) | B6: 0 | C6: 6500000 | D6: 6500000 | E6: 6500000 | F6: 6500000 | G6: 6500000 | H6: 6500000 | I6: 6500000 | J6: 6500000 | K6: 6500000 | L6: 6500000 | M6: 6500000 | N6: =SUM(B6:M6) -> 71500000
A7: Krediler | B7: =Krediler!N15+'Krediler (2)'!N6 -> 0 | C7: =Krediler!N16+'Krediler (2)'!N7 -> 0.5 | D7: =Krediler!N17+'Krediler (2)'!N8 -> 0 | E7: =Krediler!N18+'Krediler (2)'!N9 -> 2424259.7 | F7: =Krediler!N19+'Krediler (2)'!N10 -> 2690341.4 | G7: =Krediler!N20+'Krediler (2)'!N11 -> 2690341.4 | H7: =Krediler!N21+'Krediler (2)'!N12 -> 2690341.4 | I7: =Krediler!N22+'Krediler (2)'!N13 -> 2690341.4 | J7: =Krediler!N23+'Krediler (2)'!N14 -> 2690341.4 | K7: =Krediler!N24+'Krediler (2)'!N15 -> 2424259.7 | L7: =Krediler!N25+'Krediler (2)'!N16 -> 1340000.2 | M7: =Krediler!N26+'Krediler (2)'!N17 -> 0 | N7: =SUM(B7:M7) -> 19640227
A8: Çek Ödeme | B8: =Çekler!#REF! -> #REF! | C8: =Çekler!#REF! -> #REF! | D8: =Çekler!#REF! -> #REF! | E8: =Çekler!#REF! -> #REF! | F8: =Çekler!#REF! -> #REF! | G8: =Çekler!#REF! -> #REF! | H8: =Çekler!#REF! -> #REF! | I8: =Çekler!#REF! -> #REF! | ... M8: =Çekler!#REF! -> #REF! | N8: =SUM(B8:M8) -> #REF!
A9: Nakit Ödemeler Toplamı | B9: =SUM(B4:B8) -> #REF! | C9: =SUM(C4:C8) -> #REF! | D9: =SUM(D4:D8) -> #REF! | E9: =SUM(E4:E8) -> #REF! | F9: =SUM(F4:F8) -> #REF! | G9: =SUM(G4:G8) -> #REF! | H9: =SUM(H4:H8) -> #REF! | I9: =SUM(I4:I8) -> #REF! | ... M9: =SUM(M4:M8) -> #REF! | N9: =SUM(B9:M9) -> #REF!

Sheet Özet Tablo (2)
B2: =Durum!E2 -> Altan Verilecek | C2: =Durum!F2 -> Extra Ödeme Nakit | D2: =Durum!G2 -> Nakit İşçilik Dahil | E2: =Durum!H2 -> Krediler Kesintiler Toplam | F2: =Durum!I2 -> Çek Ödeme | G2: =Durum!J2 -> Nakit Ödemeler Toplamı | H2: =Durum!L2 -> Durum
A3: Ocak | B3: =Durum!E3 -> 0 | C3: =Durum!F3 -> 0 | D3: =Durum!G3 -> 0 | E3: =Durum!H3 -> 0 | F3: =Durum!I3 -> 0 | G3: =Durum!J3 -> 0 | H3: =Durum!L3 -> 0
A4: Şubat | B4: =Durum!E4 -> 1000000 | C4: =Durum!F4 -> 0 | D4: =Durum!G4 -> 6500000 | E4: =Durum!H4 -> 0.5 | F4: =Durum!I4 -> 0 | G4: =Durum!J4 -> 7500000.5 | H4: =Durum!L4 -> -7500000.5
A5: Mart | B5: =Durum!E5 -> 1000000 | C5: =Durum!F5 -> 0 | D5: =Durum!G5 -> 6500000 | E5: =Durum!H5 -> 0 | F5: =Durum!I5 -> 699686.04 | G5: =Durum!J5 -> 8199686 | H5: =Durum!L5 -> -8199686
A6: Nisan | B6: =Durum!E6 -> 1000000 | C6: =Durum!F6 -> 3300000 | D6: =Durum!G6 -> 6500000 | E6: =Durum!H6 -> 2424259.7 | F6: =Durum!I6 -> 777180 | G6: =Durum!J6 -> 14001440 | H6: =Durum!L6 -> -14001440
A7: Mayıs | B7: =Durum!E7 -> 1000000 | C7: =Durum!F7 -> 3300000 | D7: =Durum!G7 -> 6500000 | E7: =Durum!H7 -> 2690341.4 | F7: =Durum!I7 -> 685349.24 | G7: =Durum!J7 -> 14175691 | H7: =Durum!L7 -> -14175691
A8: Haziran | B8: =Durum!E8 -> 1000000 | C8: =Durum!F8 -> 0 | D8: =Durum!G8 -> 6500000 | E8: =Durum!H8 -> 2690341.4 | F8: =Durum!I8 -> 757571 | G8: =Durum!J8 -> 10947912 | H8: =Durum!L8 -> -10947912
A9: Temmuz | B9: =Durum!E9 -> 1000000 | C9: =Durum!F9 -> 0 | D9: =Durum!G9 -> 6500000 | E9: =Durum!H9 -> 2690341.4 | F9: =Durum!I9 -> 657799.42 | G9: =Durum!J9 -> 10848141 | H9: =Durum!L9 -> -10848141
A10: Ağustos | B10: =Durum!E10 -> 1000000 | C10: =Durum!F10 -> 0 | D10: =Durum!G10 -> 6500000 | E10: =Durum!H10 -> 2690341.4 | F10: =Durum!I10 -> 700000 | G10: =Durum!J10 -> 10890341 | H10: =Durum!L10 -> -10890341
A11: Eylül | B11: =Durum!E11 -> 0 | C11: =Durum!F11 -> 0 | D11: =Durum!G11 -> 6500000 | E11: =Durum!H11 -> 2690341.4 | F11: =Durum!I11 -> 500000 | G11: =Durum!J11 -> 9690341.4 | H11: =Durum!L11 -> -9690341.4
A12: Ekim | B12: =Durum!E12 -> 0 | C12: =Durum!F12 -> 0 | D12: =Durum!G12 -> 6500000 | E12: =Durum!H12 -> 2424259.7 | F12: =Durum!I12 -> 250000 | G12: =Durum!J12 -> 9174259.7 | H12: =Durum!L12 -> -9174259.7
A13: Kasım | B13: =Durum!E13 -> 0 | C13: =Durum!F13 -> 0 | D13: =Durum!G13 -> 6500000 | E13: =Durum!H13 -> 1340000.2 | F13: =Durum!I13 -> 0 | G13: =Durum!J13 -> 7840000.2 | H13: =Durum!L13 -> -7840000.2
A14: Aralık | B14: =Durum!E14 -> 0 | C14: =Durum!F14 -> 0 | D14: =Durum!G14 -> 6500000 | E14: =Durum!H14 -> 0 | F14: =Durum!I14 -> 0 | G14: =Durum!J14 -> 6500000 | H14: =Durum!L14 -> -6500000

Sheet Durum
B2: Vade | C2: Nakit Alacak | D2: Nakit Alacaklar Toplam | E2: Altan Verilecek | F2: Extra Ödeme Nakit | G2: Nakit İşçilik Dahil | H2: Krediler Kesintiler Toplam | I2: Çek Ödeme | J2: Nakit Ödemeler Toplamı | K2: GG Çek | L2: Durum
A3: 2026 | B3: Ocak | C3: 0 | D3: 0 | E3: 0 | F3: =Extra!M10 -> 0 | G3: 0 | H3: =Krediler!N15+'Krediler (2)'!N6 -> 0 | I3: =Çekler!L5 -> 0 | J3: =SUM(E3:I3) -> 0 | K3: 1200000 | L3: =D3-J3 -> 0
A4: 2026 | B4: Şubat | C4: 0 | D4: 0 | E4: 1000000 | F4: =Extra!M11 -> 0 | G4: 6500000 | H4: ='Krediler (2)'!N7 -> 0.5 | I4: =Çekler!L6 -> 0 | J4: =SUM(E4:I4) -> 7500000.5 | K4: 1200000 | L4: =D4-J4 -> -7500000.5
A5: 2026 | B5: Mart | C5: 0 | D5: 0 | E5: 1000000 | F5: =Extra!M12 -> 0 | G5: 6500000 | H5: ='Krediler (2)'!N8 -> 0 | I5: =Çekler!L7 -> 699686.04 | J5: =SUM(E5:I5) -> 8199686 | K5: 1200000 | L5: =D5-J5 -> -8199686
A6: 2026 | B6: Nisan | C6: 0 | D6: 0 | E6: 1000000 | F6: =Extra!M13 -> 3300000 | G6: 6500000 | H6: ='Krediler (2)'!N9 -> 2424259.7 | I6: =Çekler!L8 -> 777180 | J6: =SUM(E6:I6) -> 14001440 | K6: 1200000 | L6: =D6-J6 -> -14001440
A7: 2026 | B7: Mayıs | C7: 0 | D7: 0 | E7: 1000000 | F7: =Extra!M14 -> 3300000 | G7: 6500000 | H7: ='Krediler (2)'!N10 -> 2690341.4 | I7: =Çekler!L9 -> 685349.24 | J7: =SUM(E7:I7) -> 14175691 | K7: 1200000 | L7: =D7-J7 -> -14175691
A8: 2026 | B8: Haziran | C8: 0 | D8: 0 | E8: 1000000 | F8: =Extra!M15 -> 0 | G8: 6500000 | H8: ='Krediler (2)'!N11 -> 2690341.4 | I8: =Çekler!L10 -> 757571 | J8: =SUM(E8:I8) -> 10947912 | K8: 1200000 | L8: =D8-J8 -> -10947912
A9: 2026 | B9: Temmuz | C9: 0 | D9: 0 | E9: 1000000 | F9: =Extra!M16 -> 0 | G9: 6500000 | H9: ='Krediler (2)'!N12 -> 2690341.4 | I9: =Çekler!L11 -> 657799.42 | J9: =SUM(E9:I9) -> 10848141 | K9: 1200000 | L9: =D9-J9 -> -10848141
A10: 2026 | B10: Ağustos | C10: 0 | D10: 0 | E10: 1000000 | F10: =Extra!M17 -> 0 | G10: 6500000 | H10: ='Krediler (2)'!N13 -> 2690341.4 | I10: =Çekler!L12 -> 700000 | J10: =SUM(E10:I10) -> 10890341 | K10: 1200000 | L10: =D10-J10 -> -10890341
A11: 2026 | B11: Eylül | C11: 0 | D11: 0 | E11: 0 | F11: =Extra!M18 -> 0 | G11: 6500000 | H11: ='Krediler (2)'!N14 -> 2690341.4 | I11: =Çekler!L13 -> 500000 | J11: =SUM(E11:I11) -> 9690341.4 | K11: 1200000 | L11: =D11-J11 -> -9690341.4
A12: 2026 | B12: Ekim | C12: 0 | D12: 0 | E12: 0 | F12: =Extra!M19 -> 0 | G12: 6500000 | H12: ='Krediler (2)'!N15 -> 2424259.7 | I12: =Çekler!L14 -> 250000 | J12: =SUM(E12:I12) -> 9174259.7 | K12: 1200000 | L12: =D12-J12 -> -9174259.7
A13: 2026 | B13: Kasım | C13: 0 | D13: 0 | E13: 0 | F13: =Extra!M20 -> 0 | G13: 6500000 | H13: ='Krediler (2)'!N16 -> 1340000.2 | I13: =Çekler!L15 -> 0 | J13: =SUM(E13:I13) -> 7840000.2 | K13: 1200000 | L13: =D13-J13 -> -7840000.2
A14: 2026 | B14: Aralık | C14: 0 | D14: 0 | E14: 0 | F14: =Extra!M21 -> 0 | G14: 6500000 | H14: ='Krediler (2)'!N17 -> 0 | I14: =Çekler!L16 -> 0 | J14: =SUM(E14:I14) -> 6500000 | K14: 1200000 | L14: =D14-J14 -> -6500000
C16: =SUBTOTAL(9,C3:C15) -> 0 | D16: =SUBTOTAL(9,D3:D15) -> 0 | H16: =SUM(H3:H15) -> 19640227 | I16: =SUM(I3:I15) -> 5027585.7 | J16: =SUM(J3:J15) -> 1.0976781e+08

Sheet Genel gider Aylık
A1: Kod | B1: Kod Tanımı | C1: Miktar | D1: Tutar | E1: KDVTutar | F1: TevTutar | G1: StopajTutar | H1: Kur | I1: ToplamTutar
A2: B01.001 | B2: Elektrik Gideri (Tedaş) | C2: 1 | D2: 350000 | E2: 32614.31 | F2: 0 | G2: 0 | H2: TL | I2: =D2+E2 -> 382614.31
A3: B01.005 | B3: Telefon Gideri (Gsm Öperatörleri) | C3: 3 | D3: 10032.31 | E3: 0 | F3: 0 | G3: 0 | H3: TL | I3: =D3+E3 -> 10032.31
A4: B01.006 | B4: İnternet Gideri (Adsl) | C4: 1 | D4: 3291.44 | E4: 658.29 | F4: 0 | G4: 0 | H4: TL | I4: =D4+E4 -> 3949.73
A5: B03.006 | B5: İnternet Gideri (Adsl) | C5: 2 | D5: 1059.3 | E5: 0 | F5: 0 | G5: 0 | H5: TL | I5: =D5+E5 -> 1059.3
A6: B03.007 | B6: AyFiz.Pos Yaz. | C6: 0 | D6: 429 | E6: 0 | F6: 0 | G6: 0 | H6: TL | I6: =D6+E6 -> 429
A7: D01.001 | B7: SMM Danışmanlık | C7: 0 | D7: 16250 | E7: 2478.81 | F7: 0 | G7: 0 | H7: TL | I7: =D7+E7 -> 18728.81
A8: D01.002 | B8: Avukat Gideri | C8: 0 | D8: 12500 | E8: 1906.78 | F8: 0 | G8: 0 | H8: TL | I8: =D8+E8 -> 14406.78
A9: D01.005 | B9: İşletme Doktoru | C9: 1 | D9: 6363.64 | E9: 636.36 | F9: 0 | G9: 0 | H9: TL | I9: =D9+E9 -> 7000
A10: D01.006 | B10: İş Güvenliği Danışmanı | C10: 1 | D10: 2250 | E10: 450 | F10: 0 | G10: 0 | H10: TL | I10: =D10+E10 -> 2700
A11: D01.008 | B11: Mühendislik ve Teknik Danışmanlık Giderleri | C11: 1 | D11: 1625 | E11: 325 | F11: 0 | G11: 0 | H11: TL | I11: =D11+E11 -> 1950
A12: D01.009 | B12: Diğer Danışmanlık Giderleri | C12: 1 | D12: 17382.6 | E12: 3476.52 | F12: 0 | G12: 0 | H12: TL | I12: =D12+E12 -> 20859.12
A14: F01.001 | B14: Banka İlkem Komisyon ve Masrafları | C14: 0 | D14: 1378.37 | E14: 0 | F14: 0 | G14: 0 | H14: TL | I14: =D14+E14 -> 1378.37
... A22: G02.012 | B22: Tesis ve Cihaz Periyodik Bakımları | C22: 2 | D22: 7623.64 | E22: 1524.73 | F22: 0 | G22: 0 | H22: TL | I22: =D22+E22 -> 9148.37
A23: G03.001 | B23: Yemek Gideri | C23: 2775 | D23: 450000 | E23: 0 | F23: 0 | G23: 0 | H23: TL | I23: =D23+E23 -> 450000 | J23: Çek | K23: 45717
A24: G03.003 | B24: Kargo Nakliye Gideri | C24: 15 | D24: 72171.52 | E24: 11518.92 | F24: 1820 | G24: 0 | H24: TL | I24: =D24+E24 -> 83690.44
A25: G03.005 | B25: Kırtasiye Gideri | C25: 69 | D25: 10481.2 | E25: 1997.2 | F25: 0 | G25: 0 | H25: TL | I25: =D25+E25 -> 12478.4
A26: G03.011 | B26: Ulaşım ve Seyaha Gideri | C26: 1 | D26: 400000 | E26: 0 | F26: 0 | G26: 0 | H26: TL | I26: =D26+E26 -> 400000 | J26: Çek | K26: 45717
A27: G03.013 | B27: Diğer Çeşitli Giderler | C27: 8 | D27: 79579 | E27: 11020 | F27: 0 | G27: 0 | H27: TL | I27: =D27+E27 -> 90599
A28: G05.001 | B28: Merkez Kira Gideri | C28: 0 | D28: 350000 | E28: 0 | F28: 0 | G28: 0 | H28: TL | I28: =D28+E28 -> 350000 | J28: Çek | K28: 45717
A29: G05.003 | B29: Mağaza Beyazıt Kira Gideri | C29: 0 | D29: 62000 | E29: 0 | F29: 0 | G29: 0 | H29: TL | I29: =D29+E29 -> 62000
A30: G05.004 | B30: II.Fabrika Kira Gideri | C30: 1 | D30: 0 | E30: 0 | F30: 0 | G30: 0 | H30: TL | I30: =D30+E30 -> 0
A31: P01.001 | B31: Personel Maaş Ödemeleri | C31: 0 | D31: 5000000 | E31: -1400000 | F31: 0 | G31: 0 | H31: TL | I31: =D31+E31 -> 3600000 | K31: 3176917.2 | L31: Ocak Zammı Dahil değil
A32: P01.002 | B32: Personel Avans Ödemeleri | C32: 0 | D32: 84500 | E32: 0 | F32: 0 | G32: 0 | H32: TL | I32: =D32+E32 -> 84500
A33: P01.004 | B33: Personel Yol ve Ulaşım Gideri | C33: 0 | D33: 5910 | E33: 0 | F33: 0 | G33: 0 | H33: TL | I33: =D33+E33 -> 5910
A34: P01.005 | B34: Personel Yemek Gideri | C34: 3659.5 | D34: 35051.78 | E34: 334.17 | F34: 0 | G34: 0 | H34: TL | I34: =D34+E34 -> 35385.95
A35: P01.010 | B35: Personel İhtarname - Haciz V.b.. | C35: 0 | D35: 8819.85 | E35: 0 | F35: 0 | G35: 0 | H35: TL | I35: =D35+E35 -> 8819.85
A37: R01.001 | B37: Muhtasar Vergisi Ödemeleri | C37: 0 | D37: 17289.8 | E37: 0 | F37: 0 | G37: 0 | H37: TL | I37: =D37+E37 -> 17289.8
A39: R02.001 | B39: Ödenecek KDV 1 | C39: 0 | D39: 308.3 | E39: 0 | F39: 0 | G39: 0 | H39: TL | I39: =D39+E39 -> 308.3
A40: R02.005 | B40: Geçici Vergi | C40: 0 | D40: 158000 | E40: 0 | F40: 0 | G40: 0 | H40: TL | I40: =D40+E40 -> 158000 | K40: 45717
A41: R03.001 | B41: SGK Ödemeleri | C41: 0 | D41: 670000 | E41: 0 | F41: 0 | G41: 0 | H41: TL | I41: =D41+E41 -> 670000
A43: S02.006 | B43: Lazer İşçilik Gideri | C43: 0 | D43: 400 | E43: 0 | F43: 0 | G43: 0 | H43: TL | I43: 0
A44: S02.015 | B44: Saya İşçilik Gideri | C44: 0 | D44: 92840 | E44: 0 | F44: 0 | G44: 0 | H44: TL | I44: 0
A45: T01.002 | B45: Akaryakıt Gideri - 34 DD 5677 | C45: 1 | D45: 4036.23 | E45: 0 | F45: 0 | G45: 0 | H45: TL | I45: =D45+E45 -> 4036.23
A46: T01.004 | B46: Akaryakıt Gideri - 34 BPY 282 | C46: 4 | D46: 15970.77 | E46: 300 | F46: 0 | G46: 0 | H46: TL | I46: =D46+E46 -> 16270.77
A47: T01.008 | B47: Akaryakıt Gideri - 34 RP 2632 | C47: 2 | D47: 7331.23 | E47: 0 | F47: 0 | G47: 0 | H47: TL | I47: =D47+E47 -> 7331.23
A48: T01.010 | B48: Akaryakıt Gideri - 34 GFK 183 | C48: 2 | D48: 11158.49 | E48: 0 | F48: 0 | G48: 0 | H48: TL | I48: =D48+E48 -> 11158.49
A50: T02.004 | B50: Araç Bakım Onarım Gideri - 34 BPY 282 | C50: 8 | D50: 0 | E50: 0 | F50: 0 | G50: 0 | H50: TL | I50: =D50+E50 -> 0
A51: T02.008 | B51: Araç Bakım Onarım Gideri - 34 RP 2632 | C51: 8.01 | D51: 0 | E51: 0 | F51: 0 | G51: 0 | H51: TL | I51: =D51+E51 -> 0
A53: T03.099 | B53: Otopark Gideri - Diğer | C53: 0 | D53: 2925 | E53: 0 | F53: 0 | G53: 0 | H53: TL | I53: =D53+E53 -> 2925
...

Sheet Not
K1: 45975 | L1: Yazılan Notlar
A2: 20 Ağustos iti bari ile elimizde öngörülen Siparişler Tamamlanmış olur | G2: İşçilik | I2: Birim Fiyat | K2: Maas | L2: 2600000 | M2: Ödendi | N2: maaş
A3: 45884 | C3: Enjeksiyon grubu | D3: 15 gün ücretli | E3: 15 gün ücretsiz izine gönderelim | G3: Eva Enjeksiyon | I3: 33.8 | K3: serkan | L3: 461900 | M3: Ödendi | N3: İşlenecek | Q3: Kasa | R3: 1734000
A4: 45899 | C4: Monta | D4: 15 gün ücretli | E4: 15 gün ücretsiz izine gönderelim | G4: Patch Yapıştırma | H4: x1 | I4: 4.15 | K4: Sahin taban. Kuveytturk Kart | L4: 380000 | M4: Ödendi | N4: İşlenecek | O4: Banka | Q4: Adem İbrahimoğlu | R4: -542750
G5: Patch Yapıştırma | H5: x3 | I5: 10.35 | K5: Nexgen KMH | L5: 100000 | M5: Ödendi | N5: İşlenecek | O5: Banka | Q5: Şahin Terzi Kart | R5: -230000
A6: ugg konteynerlar için | C6: 10-22 Temmuz arası | D6: Kasada olması gereken tutar | G6: Işık montaj sarma | I6: 5.6 | K6: Bilir gümrük | L6: 265000 | M6: Ödendi | N6: İşlenecek | O6: Cariye | Q6: Kubilay kart Garanti | R6: -82491.36
C7: 4000000 | G7: Vardola Sargı işçilik | I7: 11.35 | K7: SAHIN TABAN TEB KART | L7: 240000 | M7: Ödendi | N7: İşlenecek | O7: Banka | Q7: Sahin taban Vergi | R7: -460000
G8: Sim Uygulama | I8: 25.5 | K8: FINANSBANK sahin taban kart | L8: 80000 | M8: Ödendi | N8: İşlenecek | O8: Banka | Q8: Nexgen vergi | R8: -190000
K9: KADIM ORTAK SAGLIK | L9: 170810 | M9: Ödendi | N9: İşlenecek | O9: Cariye
G10: Genel Gider | I10: 28 | Q10: Rafet aydın | R10: -39600 | S10: Ödendi
K11: Sahin taban Vergi | L11: 460000 | M11: Vergi | Q11: Mehmet Uzunali | R11: =-40600 -> -40600 | S11: Ödendi
K12: Nexgen vergi | L12: 190000 | M12: Vergi | Q12: Mesut Keskin | R12: -7200 | S12: Ödendi
K13: Pera. | L13: 75000 | M13: Vergi | R13: =SUM(R3:R12) -> 141358.64
K15: Kubilay | L15: 347490 | M15: Gecikmede | O15: Listede var
K16: Adem Ibrahimoglu | L16: 542750 | M16: Gecikmede | N16: 45968 | O16: Listede var | P16: Ödendi
K17: Sahin Terzi Finans bank. | L17: 230000 | M17: Gecikmede | N17: 45 gün | O17: Listede var
K18: Esra orhan | L18: 750000 | M18: Gecikmede | O18: Listede var
K19: Efsun akyuz | L19: 70000 | O19: Listede var
K20: furkan | L20: 500000 | M20: Gecikmede | O20: Listede var
K21: Serhat | L21: 200000 | O21: Listede var
K22: Ibrahim Kilic | L22: 1250000 | O22: Listede var
K23: Sinan ates kmh | L23: 110000 | M23: Gecikmede | O23: Listede var
K24: Sinan Ates kkredi karti | L24: 210000 | M24: Gecikmede | O24: Listede var
K25: Metin Can EMIN KART. | L25: 250000 | M25: 45971 | O25: Listede var
K26: Altan terzi garanti | L26: 648116 | M26: 45982 | O26: Listede var
